Error : when validating test22::foo
 --> test_resources/control_flow/test22.yr:(1,4)
 1  ┃ fn foo ()
    ╋    ^^^
    ┃ Error : unreachable statement
    ┃  --> test_resources/control_flow/test22.yr:(4,9)
    ┃  4  ┃     let _ = {
    ┃     ╋         ^
    ┃     ┃ Note : exiting scope here
    ┃     ┃  --> test_resources/control_flow/test22.yr:(5,9)
    ┃     ┃  5  ┃         throw copy AssertError ("");
    ┃     ┃     ╋         ^^^^^
    ┃     ┃     ┗━━━━━━━
    ┃     ┗━━━━━┻━
    ┗━━━━━┻━
Error : when validating test22::main
 --> test_resources/control_flow/test22.yr:(9,4)
 9  ┃ fn main () {
    ╋    ^^^^
    ┃ Error : unreachable statement
    ┃  --> test_resources/control_flow/test22.yr:(10,9)
    ┃ 10  ┃     let _ = {
    ┃     ╋         ^
    ┃     ┃ Note : exiting scope here
    ┃     ┃  --> test_resources/control_flow/test22.yr:(11,9)
    ┃     ┃ 11  ┃         return;
    ┃     ┃     ╋         ^^^^^^
    ┃     ┃     ┗━━━━━━━
    ┃     ┗━━━━━┻━
    ┃ Error : unreachable statement
    ┃  --> test_resources/control_flow/test22.yr:(15,13)
    ┃ 15  ┃         let _ = {
    ┃     ╋             ^
    ┃     ┃ Note : exiting scope here
    ┃     ┃  --> test_resources/control_flow/test22.yr:(16,13)
    ┃     ┃ 16  ┃             break 12;
    ┃     ┃     ╋             ^^^^^
    ┃     ┃     ┗━━━━━━━
    ┃     ┗━━━━━┻━
    ┗━━━━━┻━
