frame : test12::main ()-> void {
    let a : fn ()-> void = fn test12::foo;
    (a)();
    <unit-value>
}
frame : test12::foo ()-> void try {
    {
        #{
            throw core::exception::AssertError::self(new, ""s8)
        #};
        <unit-value>
    }
} catch {
    let #_catch : &(core::exception::AssertError)
    if ((true && true) && #{
        let _ : &(core::exception::AssertError) = #_catch;
        true
    #}) {
        {
            <unit-value>
        }
    }
}
