frame : test12::foo ()-> void try {
    {
        throw core::exception::assertion::AssertError::self(new, ""s8);
        <unit-value>
    }
} catch {
    let #_catch : &(core::exception::assertion::AssertError)
    if ((true && true) && #{
        let _ : &(core::exception::assertion::AssertError) = #_catch;
        true
    #}) {
        {
            <unit-value>
        }
    }
}
frame : test12::main ()-> void {
    let a : fn ()-> void = fn test12::foo;
    (a)();
    <unit-value>
}
