Error : when validating
 --> test_resources/lit_class/ctors/test7.yr:(8,8)
 8  ┃ record A {
    ╋        ^
    ┃ Error : when validating test7::A::self
    ┃  --> test_resources/lit_class/ctors/test7.yr:(11,9)
    ┃ 11  ┃     pub self ()
    ┃     ╋         ^^^^
    ┃     ┃ Error : the function test7::A::self might throw an exception of type core::exception::assertion::AssertError, but that is not declared in its prototype
    ┃     ┃  --> test_resources/lit_class/ctors/test7.yr:(11,9)
    ┃     ┃ 11  ┃     pub self ()
    ┃     ┃     ╋         ^^^^
    ┃     ┃     ┃ Note :
    ┃     ┃     ┃  --> test_resources/lit_class/ctors/test7.yr:(12,22)
    ┃     ┃     ┃ 12  ┃         with a = foo ()
    ┃     ┃     ┃     ╋                      ^
    ┃     ┃     ┃     ┗━━━━━━━
    ┃     ┃     ┗━━━━━┻━
    ┃     ┗━━━━━┻━
    ┗━━━━━┻━
