fn main ()
{
    {
    } exit {
        {
            throw AssertError::new ("Error");
        } catch {
            _ => { }
        }
    }
}
