Error : when validating test4::main
 --> test_resources/scope_guards/test4.yr:(20,4)
20  ┃ fn main ()
    ╋    ^^^^
    ┃ Error : when validating catching pattern with type &(core::exception::Exception)
    ┃  --> test_resources/scope_guards/test4.yr:(24,7)
    ┃ 24  ┃     } catch {
    ┃     ╋       ^^^^^
    ┃     ┃ Error : Exception type test4::C is already caught by another catching pattern of type test4::B
    ┃     ┃  --> test_resources/scope_guards/test4.yr:(29,11)
    ┃     ┃ 29  ┃         C () => {
    ┃     ┃     ╋           ^
    ┃     ┃    ...
    ┃     ┃  --> test_resources/scope_guards/test4.yr:(25,11)
    ┃     ┃ 25  ┃         B ()  => {
    ┃     ┃     ╋           ^
    ┃     ┃     ┗━━━━━━━
    ┃     ┗━━━━━┻━
    ┗━━━━━┻━
